Traceback (most recent call last):
  File "/home/serah/anaconda3/lib/python3.10/site-packages/pandas/core/indexes/base.py", line 3802, in get_loc
    return self._engine.get_loc(casted_key)
  File "pandas/_libs/index.pyx", line 138, in pandas._libs.index.IndexEngine.get_loc
  File "pandas/_libs/index.pyx", line 165, in pandas._libs.index.IndexEngine.get_loc
  File "pandas/_libs/hashtable_class_helper.pxi", line 5745, in pandas._libs.hashtable.PyObjectHashTable.get_item
  File "pandas/_libs/hashtable_class_helper.pxi", line 5753, in pandas._libs.hashtable.PyObjectHashTable.get_item
KeyError: 'body_text'

The above exception was the direct cause of the following exception:

Traceback (most recent call last):
  File "/home/serah/serah-summer23/preprocessing.py", line 29, in <module>
    body_text = df.loc[:, 'body_text']
  File "/home/serah/anaconda3/lib/python3.10/site-packages/pandas/core/indexing.py", line 1067, in __getitem__
    return self._getitem_tuple(key)
  File "/home/serah/anaconda3/lib/python3.10/site-packages/pandas/core/indexing.py", line 1247, in _getitem_tuple
    return self._getitem_lowerdim(tup)
  File "/home/serah/anaconda3/lib/python3.10/site-packages/pandas/core/indexing.py", line 967, in _getitem_lowerdim
    section = self._getitem_axis(key, axis=i)
  File "/home/serah/anaconda3/lib/python3.10/site-packages/pandas/core/indexing.py", line 1312, in _getitem_axis
    return self._get_label(key, axis=axis)
  File "/home/serah/anaconda3/lib/python3.10/site-packages/pandas/core/indexing.py", line 1260, in _get_label
    return self.obj.xs(label, axis=axis)
  File "/home/serah/anaconda3/lib/python3.10/site-packages/pandas/core/generic.py", line 4041, in xs
    return self[key]
  File "/home/serah/anaconda3/lib/python3.10/site-packages/pandas/core/frame.py", line 3807, in __getitem__
    indexer = self.columns.get_loc(key)
  File "/home/serah/anaconda3/lib/python3.10/site-packages/pandas/core/indexes/base.py", line 3804, in get_loc
    raise KeyError(key) from err
KeyError: 'body_text'
